<?xml version="1.0" ?>
<!-- =================================================================================== -->
<!-- |    This document was autogenerated by xacro from test.xacro                     | -->
<!-- |    EDITING THIS FILE BY HAND IS NOT RECOMMENDED                                 | -->
<!-- =================================================================================== -->
<robot>
  <!-- 各个link -->
  <link name="base_link">
    <inertial>
      <origin rpy="0 0 0" xyz="-0.00112 0.03727 -0.00505"/>
      <mass value="2.2956"/>
      <!-- mass kg -->
      <inertia ixx="0.003765" ixy="-8.39e-6" ixz="1.11e-7" iyy="0.009989" iyz="-7.96e-8" izz="0.008215"/>
      <!-- mass martrix -->
    </inertial>
    <visual>
      <origin rpy="1.57 0 3.14" xyz="0 0 0"/>
      <geometry>
        <mesh filename="../meshes/base_link.STL"/>
      </geometry>
      <material name="silver">
        <color rgba="0.8 0.8 0.8 1"/>
      </material>
    </visual>
    <collision>
      <origin rpy="1.57 0 3.14" xyz="0 0 0"/>
      <geometry>
        <mesh filename="../meshes/base_link.STL"/>
      </geometry>
    </collision>
  </link>
  <link name="thigh1_Link">
    <inertial>
      <origin rpy="0 0 0" xyz="0.055 -0.0634 -0.0216"/>
      <mass value="0.1971"/>
      <inertia ixx="0.000242" ixy="0.000152" ixz="0" iyy="0.000196" iyz="0" izz="0.000432"/>
    </inertial>
    <visual>
      <origin rpy="0 0 0" xyz="0 0 0"/>
      <geometry>
        <mesh filename="../meshes/thigh1_Link.STL"/>
      </geometry>
      <material name="blue">
        <color rgba="0.8 0.8 0.8 1"/>
      </material>
    </visual>
    <collision>
      <origin rpy="0 0 0" xyz="0 0 0"/>
      <geometry>
        <mesh filename="../meshes/thigh1_Link.STL"/>
      </geometry>
    </collision>
  </link>
  <link name="calf1_Link">
    <inertial>
      <origin rpy="0 0 0" xyz="-0.129 -0.0864 -0.0114"/>
      <mass value="0.2084"/>
      <inertia ixx="0.000443" ixy="-0.000512" ixz="0" iyy="0.000859" iyz="0" izz="0.001298"/>
    </inertial>
    <visual>
      <origin rpy="0 0 0" xyz="0 0 0"/>
      <geometry>
        <mesh filename="../meshes/calf1_Link.STL"/>
      </geometry>
      <material name="silver">
        <color rgba="0.8 0.8 0.8 1"/>
      </material>
    </visual>
    <collision>
      <origin rpy="0 0 0" xyz="0 0 0"/>
      <geometry>
        <mesh filename="../meshes/calf1_Link.STL"/>
      </geometry>
    </collision>
  </link>
  <link name="wheel1_Link">
    <inertial>
      <origin rpy="0 0 0" xyz="0 0 0.025"/>
      <mass value="1.2715"/>
      <inertia ixx="0.00354" ixy="0" ixz="0" iyy="0.00354" iyz="0" izz="0.00682"/>
    </inertial>
    <visual>
      <origin rpy="0 0 0" xyz="0 0 0"/>
      <geometry>
        <mesh filename="../meshes/wheel1_Link.STL"/>
      </geometry>
      <material name="red">
        <color rgba="0.8 0.8 0.8 1"/>
      </material>
    </visual>
    <collision>
      <origin rpy="0 0 0" xyz="0 0 0"/>
      <geometry>
        <mesh filename="../meshes/wheel1_Link.STL"/>
      </geometry>
    </collision>
  </link>
  <link name="thigh2_Link">
    <inertial>
      <origin rpy="0 0 0" xyz="0.0769 -0.0337 0.0216"/>
      <mass value="0.1971"/>
      <inertia ixx="0.000114" ixy="0.000112" ixz="0" iyy="0.000324" iyz="0" izz="0.000432"/>
    </inertial>
    <visual>
      <origin rpy="0 0 0" xyz="0 0 0"/>
      <geometry>
        <mesh filename="../meshes/thigh2_Link.STL"/>
      </geometry>
      <material name="blue">
        <color rgba="0.8 0.8 0.8 1"/>
      </material>
    </visual>
    <collision>
      <origin rpy="0 0 0" xyz="0 0 0"/>
      <geometry>
        <mesh filename="../meshes/thigh2_Link.STL"/>
      </geometry>
    </collision>
  </link>
  <link name="calf2_Link">
    <inertial>
      <origin rpy="0 0 0" xyz="-0.115 0.104 -0.0114"/>
      <mass value="0.2084"/>
      <inertia ixx="0.000596" ixy="0.000549" ixz="0" iyy="0.000706" iyz="0" izz="0.001298"/>
    </inertial>
    <visual>
      <origin rpy="0 0 0" xyz="0 0 0"/>
      <geometry>
        <mesh filename="../meshes/calf2_Link.STL"/>
      </geometry>
      <material name="silver">
        <color rgba="0.8 0.8 0.8 1"/>
      </material>
    </visual>
    <collision>
      <origin rpy="0 0 0" xyz="0 0 0"/>
      <geometry>
        <mesh filename="../meshes/calf2_Link.STL"/>
      </geometry>
    </collision>
  </link>
  <link name="wheel2_Link">
    <inertial>
      <origin rpy="0 0 0" xyz="0 0 0.025"/>
      <mass value="1.2715"/>
      <inertia ixx="0.00354" ixy="0" ixz="0" iyy="0.00354" iyz="0" izz="0.00682"/>
    </inertial>
    <visual>
      <origin rpy="0 0 0" xyz="0 0 0"/>
      <geometry>
        <mesh filename="../meshes/wheel2_Link.STL"/>
      </geometry>
      <material name="red">
        <color rgba="0.8 0.8 0.8 1"/>
      </material>
    </visual>
    <collision>
      <origin rpy="0 0 0" xyz="0 0 0"/>
      <geometry>
        <mesh filename="../meshes/wheel2_Link.STL"/>
      </geometry>
    </collision>
  </link>
  <!-- joints -->
  <joint name="joint1" type="revolute">
    <origin rpy="1.57 0 3.14" xyz="-0.054991 -0.179 0.060002"/>
    <parent link="base_link"/>
    <child link="thigh1_Link"/>
    <axis xyz="0 0 1"/>
    <limit effort="1" lower="5.9" upper="7.39" velocity="1"/>
    <dynamics damping="1"/>
    <initial_position>6.2</initial_position>
  </joint>
  <joint name="joint2" type="revolute">
    <origin rpy="-3.1416 0 1.5708" xyz="0.098406 -0.11321 -0.0508"/>
    <parent link="thigh1_Link"/>
    <child link="calf1_Link"/>
    <axis xyz="0 0 -1"/>
    <limit effort="1" lower="5" upper="6.74" velocity="1"/>
    <dynamics damping="1"/>
    <initial_position>0</initial_position>
  </joint>
  <joint name="joint3" type="continuous">
    <origin rpy="3.1416 0 1.5708" xyz="-0.19921 -0.13384 0.0502"/>
    <parent link="calf1_Link"/>
    <child link="wheel1_Link"/>
    <axis xyz="0 0 -1"/>
    <limit effort="0" lower="0" upper="0" velocity="0"/>
    <dynamics damping="1"/>
    <initial_position>0</initial_position>
  </joint>
  <joint name="joint4" type="revolute">
    <origin rpy="1.57 0 3.14" xyz="-0.054991 0.179 0.060002"/>
    <parent link="base_link"/>
    <child link="thigh2_Link"/>
    <axis xyz="0 0 1"/>
    <limit effort="1" lower="5.45" upper="6.95" velocity="1"/>
    <dynamics damping="1"/>
    <initial_position>6.2</initial_position>
  </joint>
  <joint name="joint5" type="revolute">
    <origin rpy="0 0 1.5708" xyz="0.13731 -0.06037 0.0523"/>
    <parent link="thigh2_Link"/>
    <child link="calf2_Link"/>
    <axis xyz="0 0 1"/>
    <limit effort="1" lower="-0.68" upper="1.06" velocity="1"/>
    <dynamics damping="1"/>
    <initial_position>0</initial_position>
  </joint>
  <joint name="joint6" type="continuous">
    <origin rpy="3.14159265358979 0 1.5707963267949" xyz="-0.177825913114533 0.161176749639925 0.0502000000001869"/>
    <parent link="calf2_Link"/>
    <child link="wheel2_Link"/>
    <axis xyz="0 0 1"/>
    <limit effort="0" lower="0" upper="0" velocity="0"/>
    <dynamics damping="1"/>
    <initial_position>0</initial_position>
  </joint>
</robot>
