<?xml version="1.0"?>
<robot name="balance_robot" >

  <link name="base_link">
    <inertial>
      <origin xyz="-0.00112373855262246 0.0372692656695016 -0.00505390752760995" rpy="0 0 0"/>
      <mass value="2.29560503416328"/>
      <inertia 
        ixx="0.0037652524574977"
        ixy="-8.39163146332236E-06"
        ixz="1.11177265740483E-07"
        iyy="0.00998917390732425"
        iyz="-7.95593211713064E-08"
        izz="0.00821541688139456"/>
    </inertial>
    <visual>
      <origin xyz="0 0 0" rpy="1.57 0 3.14"/>
      <geometry>_model_backup
        <mesh filename="../meshes/base_link.STL"/>
        <!-- 绝对路径,相对路径并不知道这个路径基于哪 -->
      </geometry>
      <material name="silver">
        <color rgba="0.75294 0.75294 0.75294 1"/>
      </material>
    </visual>
    <collision>
    <origin
        xyz="0 0 0"
        rpy="1.57 0 3.14" />
      <geometry>
        <mesh filename="../meshes/base_link.STL"/>
      </geometry>
    </collision>
  </link>

  <link name="thigh1_Link">
    <inertial>
      <origin xyz="0.0549739524249132 -0.0633968332145482 -0.0216350771725319"
        rpy="0 0 0"/>
      <mass value="0.197086182866456"/>
      <inertia 
        ixx="0.00024192170704429"
        ixy="0.000151596293732481"
        ixz="2.91895926997022E-11"
        iyy="0.000195801576678568"
        iyz="1.66239016445694E-11"
        izz="0.000431778200595163"/>
    </inertial>
    <visual>
      <origin xyz="0 0 0" rpy="0 0 0"/>
      <geometry>
        <mesh filename="../meshes/thigh1_Link.STL"/>
      </geometry>
      <material name="blue">
        <color rgba="0.792156862745098 0.819607843137255 0.933333333333333 1"/>
      </material>
    </visual>
    <collision>
    <origin
        xyz="0 0 0"
        rpy="0 0 0" />
      <geometry>
        <mesh filename="../meshes/thigh1_Link.STL"/>
      </geometry>
    </collision>
  </link>

  <link name="calf1_Link">
    <inertial>
      <origin 
        xyz="-0.128551417489817 -0.0864244138467356 -0.0113562227771212"
        rpy="0 0 0"/>
      <mass value="0.208436751969881"/>
      <inertia 
        ixx="0.000443077458269161"
        ixy="-0.000511530679444879"
        ixz="-1.24664032712872E-19"
        iyy="0.000858907856856323"
        iyz="-1.69068272869795E-19"
        izz="0.00129794093249004"/>
    </inertial>
    <visual>
      <origin xyz="0 0 0" rpy="0 0 0"/>
      <geometry>
        <mesh filename="../meshes/calf1_Link.STL"/>
      </geometry>
      <material name="silver">
        <color rgba="0.792156862745098 0.819607843137255 0.933333333333333 1"/>
      </material>
    </visual>
    <collision>
    <origin
        xyz="0 0 0"
        rpy="0 0 0" />
      <geometry>
        <mesh filename="../meshes/calf1_Link.STL"/>
      </geometry>
    </collision>
  </link>

  <link name="wheel1_Link">
    <inertial>
      <origin
        xyz="0 0 0"
        rpy="0 0 0" />
      <mass
        value="1.27149052423921" />
      <inertia
        ixx="0.00354363099249304"
        ixy="1.46418108962828E-06"
        ixz="-2.07730661435595E-07"
        iyy="0.00354550457608862"
        iyz="2.58120287120464E-07"
        izz="0.00682215215105163" />
    </inertial>
    <visual>
      <origin xyz="0 0 0" rpy="0 0 0"/>
      <geometry>
        <mesh filename="../meshes/wheel1_Link.STL"/>
      </geometry>
      <material name="silver">
        <color
          rgba="0.752941176470588 0.752941176470588 0.752941176470588 1" />
      </material>
    </visual>
    <collision>
    <origin
        xyz="0 0 0"
        rpy="0 0 0" />
      <geometry>
        <mesh filename="../meshes/wheel1_Link.STL"/>
      </geometry>
    </collision>
  </link>

  <link name="thigh2_Link">
    <inertial>
      <origin
        xyz="0.0768523512232688 -0.0336792891394732 0.0216350771196192"
        rpy="0 0 0" />
      <mass
        value="0.197086183366415" />
      <inertia
        ixx="0.000113935088510005"
        ixy="0.000111819592475334"
        ixz="7.18924455660587E-12"
        iyy="0.000323788195216852"
        iyz="3.27930467999739E-11"
        izz="0.00043177820060005" />
    </inertial>
    <visual>
      <origin
        xyz="0 0 0"
        rpy="0 0 0" />
      <geometry>
        <mesh filename="../meshes/thigh2_Link.STL"/>
      </geometry>
      <material name="blue">
        <color
          rgba="0.792156862745098 0.819607843137255 0.933333333333333 1" />
      </material>
    </visual>
    <collision>
    <origin
        xyz="0 0 0"
        rpy="0 0 0" />
      <geometry>
        <mesh filename="../meshes/thigh2_Link.STL"/>
      </geometry>
    </collision>
  </link>

  <link name="calf2_Link">
    <inertial>
      <origin
        xyz="-0.114804441044794 0.103993204411565 -0.0113562227771211"
        rpy="0 0 0" />
      <mass
        value="0.208436751969882" />
      <inertia
        ixx="0.000596031088521595"
        ixy="0.000549428423035399"
        ixz="-1.25010431572427E-19"
        iyy="0.000705954226603891"
        iyz="3.43208632223762E-20"
        izz="0.00129794093249004" />
    </inertial>
    <visual>
      <origin xyz="0 0 0" rpy="0 0 0"/>
      <geometry>
        <mesh filename="../meshes/calf2_Link.STL"/>
      </geometry>
      <material name="silver">
        <color
          rgba="0.792156862745098 0.819607843137255 0.933333333333333 1" />
      </material>
    </visual>
    <collision>
    <origin
        xyz="0 0 0"
        rpy="0 0 0" />
      <geometry>
        <mesh filename="../meshes/calf2_Link.STL"/>
      </geometry>
    </collision>
  </link>

  <link name="wheel2_Link">
    <inertial>
      <origin
        xyz="-4.31229370099484E-05 -5.94127449699833E-05 0.0251812532780945"
        rpy="0 0 0" />
      <mass
        value="1.27149052423921" />
      <inertia
        ixx="0.00354289024620187"
        ixy="-4.55270354534913E-07"
        ixz="3.20206228643419E-07"
        iyy="0.00354624532237979"
        iyz="-8.51239183141634E-08"
        izz="0.00682215215105163" />
    </inertial>
    <visual>
      <origin xyz="0 0 0" rpy="0 0 0"/>
      <geometry>
        <mesh filename="../meshes/wheel2_Link.STL"/>
      </geometry>
      <material name="silver">
        <color
          rgba="0.752941176470588 0.752941176470588 0.752941176470588 1" />
      </material>
    </visual>
    <collision>
    <origin
        xyz="0 0 0"
        rpy="0 0 0" />
      <geometry>
        <mesh filename="../meshes/wheel2_Link.STL"/>
      </geometry>
    </collision>
  </link>

  <joint
    name="joint1"
    type="revolute">
    <origin
      xyz="-0.054991 -0.179 0.060002"
      rpy="1.57 0 3.14" />
    <parent
      link="base_link" />
    <child
      link="thigh1_Link" />
    <axis
      xyz="0 0 1" />
    <limit
      lower="5.9"
      upper="7.39"
      effort="0"
      velocity="0" />
  </joint>

  <joint
    name="joint2"
    type="revolute">
    <origin
      xyz="0.098406 -0.11321 -0.0508"
      rpy="-3.1416 0 1.5708" />
    <parent
      link="thigh1_Link" />
    <child
      link="calf1_Link" />
    <axis
      xyz="0 0 -1" />
    <limit
      lower="5"
      upper="6.74"
      effort="0"
      velocity="0" />
  </joint>

  <joint
    name="joint3"
    type="continuous">
    <origin
      xyz="-0.19921 -0.13384 0.0502"
      rpy="3.1416 0 1.5708" />
    <parent
      link="calf1_Link" />
    <child
      link="wheel1_Link" />
    <axis
      xyz="0 0 -1" />
    <limit
      lower="0"
      upper="0"
      effort="0"
      velocity="0" />
  </joint>

  <joint
    name="joint4"
    type="revolute">
    <origin
      xyz="-0.054991 0.179 0.060002"
      rpy="1.57 0 3.14" />
    <parent
      link="base_link" />
    <child
      link="thigh2_Link" />
    <axis
      xyz="0 0 1" />
    <limit
      lower="5.45"
      upper="6.95"
      effort="0"
      velocity="0" />
  </joint>

  <joint
    name="joint5"
    type="revolute">
    <origin
      xyz="0.13731 -0.06037 0.0523"
      rpy="0 0 1.5708" />
    <parent
      link="thigh2_Link" />
    <child
      link="calf2_Link" />
    <axis
      xyz="0 0 1" />
    <limit
      lower="-0.68"
      upper="1.06"
      effort="0"
      velocity="0" />
  </joint>

  <joint
    name="joint6"
    type="continuous">
    <origin
      xyz="-0.177825913114533 0.161176749639925 0.0502000000001869"
      rpy="3.14159265358979 0 1.5707963267949" />
    <parent
      link="calf2_Link" />
    <child
      link="wheel2_Link" />
    <axis
      xyz="0 0 1" />
    <limit
      lower="0"
      upper="0"
      effort="0"
      velocity="0" />
  </joint>

  <gazebo>
    <plugin filename="libgazebo_ros2_control.so" name="ros2_control">
      <parameters>$(find balance_model)/config/controllers.yaml</parameters>
      <controller_manager_node_name>controller_manager</controller_manager_node_name>
    </plugin>

    <sensor name="imu_sensor" type="imu">
      <always_on>true</always_on>
      <update_rate>100</update_rate>
      <plugin filename="libgazebo_ros_imu_sensor.so" name="imu_plugin">
        <ros>
          <qos>reliable</qos>
          <namespace>/balance_robot</namespace>
        </ros>
        <frame_name>imu_link</frame_name>
      </plugin>
    </sensor>
  </gazebo>

</robot>